Workbook
Name FFFF: Tracking!$E:$E,Tracking!$3:$25
Name FOCUS: Fondi_PE!#REF!
Name FOCUS: 'Int''l'!#REF!
Name FOCUS: Staffing!#REF!
Name FOCUS: Tracking!#REF!
Name FOCUS: '[1]Orig Dash (OLD)'!#REF!
Name Print: Tracking!$E:$E,Tracking!$3:$25
Name Print_Titles1: Tracking!$E:$E,Tracking!$3:$25

Sheet Tracking
BC1: |
E2: =+WEEKNUM(TODAY()) -> 2 | G2: NON MODIFICARE CELLE CONTENTENTI FORMULE (ES. B,C,D) | AI2: cls | AJ2: =+COUNTIF($D:$D,AI2) -> 24 | AM2: sgn | AN2: =+COUNTIF($D:$D,AM2) -> 7 | AP2: wip | AQ2: =+COUNTIF($D:$D,AP2) -> 10 | AS2: hld | AT2: =+COUNTIF($D:$D,AS2) -> 120 | AV2: abt | AW2: =+COUNTIF($D:$D,AV2) -> 345 | AY2: RIP | AZ2: =+COUNTIF($D:$D,AY2) -> 0 | BC2: |
B3: Ordine | C3: # | D3: Status | E3: Nome | F3: Codename | G3: Provincia | H3: P.IVA | I3: ATECO 2007 | J3: Settore | K3: Attività | L3: Riferimento cliente | M3: Azionista_1 | N3: Azionista_2 | O3: Presidente | P3: AD | Q3: Pres.Col.Sind | S3: Cons | T3: Anno | U3: Sales | V3: Ebitda | W3: Ebitda(%) | X3: Ut. Netto | Y3: IFN | AA3: Fonte | AB3: Segnalatore EXT | AC3: Relazione @BCA | AD3: In Charge @BCA | AE3: Staff_1 | AF3: Staff_2 | AG3: Note | AI3: Days since idea | AJ3: Days since progress | AK3: Tipologia di Incarico | AL3: Progress | AM3: Idea | AN3: 1° Contatto | AO3: Re-call | AP3: Contatto aperto | AQ3: Meet_1 / Call | AR3: Meet_2 | AS3: Meet_3 (Pitch) | AT3: (Draft EL) Meet_4 | AU3: Meet_5 | AV3: Signed | AW3: Progress | AX3: On-hold | AY3: Aborted | AZ3: Closed | BA3: % @abor | BB3: RIP | BC3: |
B5: =IF(D5=$A$516,1,IF(D5=$A$517,2,IF(D5=$A$518,3,IF(D5=$A$519,4,IF(D5=$A$520,5,IF(D5=$A$521,6)))))) -> 1 | C5: =+COUNTIF(D:D,"cls") -> 24 | D5: =IF(AL5="Closed","cls",IF(AL5=1,"sgn",IF(AL5="On-hold","hld",IF(AL5="Aborted","abt",IF(AL5<1,"wip","RIP"))))) -> cls | E5: P&B C.so Italia | J5: Education | K5: Gestione di strutture scolastiche | L5: Odile Broglin | AA5: Relazione | AC5: LOM | AD5: LOM | AE5: LUS | AG5: Fee Sharing con Alessandro Piona | AI5: =+TODAY()-AM5 -> 1467 | AJ5: =+(IF(AL5="Closed","-",IF(TODAY()-MAX(AN5:BA5)>0,TODAY()-MAX(AN5:BA5),0))) -> - | AK5: Buy Side | AL5: =+IF(BB5="",IF(AZ5="",IF(AY5="",IF(AX5="",COUNTA(AN5:AV5)/9,"On-hold"),"Aborted"),"Closed"),"RIP") -> Closed | AM5: 44197 | AN5: =+AM5 -> 44197 | AO5: na | AP5: na | AQ5: =+AN5 -> 44197 | AR5: =+AQ5 -> 44197 | AS5: na | AT5: na | AU5: na | AV5: na | AZ5: 44377 | BC5: |
B6: =IF(D6=$A$516,1,IF(D6=$A$517,2,IF(D6=$A$518,3,IF(D6=$A$519,4,IF(D6=$A$520,5,IF(D6=$A$521,6)))))) -> 1 | D6: =IF(AL6="Closed","cls",IF(AL6=1,"sgn",IF(AL6="On-hold","hld",IF(AL6="Aborted","abt",IF(AL6<1,"wip","RIP"))))) -> cls | E6: Ala | G6: TO | H6: 06239191213 | J6: Aerospace | K6: Components for aerospace industry | AA6: Relazione | AC6: LOM | AD6: LOM | AI6: =+TODAY()-AM6 -> 1286 | AJ6: =+(IF(AL6="Closed","-",IF(TODAY()-MAX(AN6:BA6)>0,TODAY()-MAX(AN6:BA6),0))) -> - | AK6: Altro | AL6: =+IF(BB6="",IF(AZ6="",IF(AY6="",IF(AX6="",COUNTA(AN6:AV6)/9,"On-hold"),"Aborted"),"Closed"),"RIP") -> Closed | AM6: 44378 | AN6: 44378 | AO6: na | AP6: na | AQ6: =+AN6 -> 44378 | AR6: na | AS6: na | AT6: na | AU6: na | AV6: na | AZ6: 44467 | BC6: |
B7: =IF(D7=$A$516,1,IF(D7=$A$517,2,IF(D7=$A$518,3,IF(D7=$A$519,4,IF(D7=$A$520,5,IF(D7=$A$521,6)))))) -> 1 | D7: =IF(AL7="Closed","cls",IF(AL7=1,"sgn",IF(AL7="On-hold","hld",IF(AL7="Aborted","abt",IF(AL7<1,"wip","RIP"))))) -> cls | E7: Bolaffi (Beyoncé - Minoranza) | F7: Beyonce | G7: TO | H7: 10156770017 | I7: 477700 | J7: Retail | K7: Commercio oro da investimento | L7: F. Bolaffi | S7: no | T7: 2019 | U7: 23.32 | V7: 0.77 | W7: 0.033018868 | X7: 0.52 | Y7: -0.1 | AA7: Relazione | AC7: LOM | AD7: ASC | AE7: PAD | AH7: 1 | AI7: =+TODAY()-AM7 -> 1528 | AJ7: =+(IF(AL7="Closed","-",IF(TODAY()-MAX(AN7:BA7)>0,TODAY()-MAX(AN7:BA7),0))) -> - | AK7: Buy Side | AL7: =+IF(BB7="",IF(AZ7="",IF(AY7="",IF(AX7="",COUNTA(AN7:AV7)/9,"On-hold"),"Aborted"),"Closed"),"RIP") -> Closed | AM7: 44136 | AN7: 44136 | AO7: na | AP7: 44136 | AQ7: 44136 | AR7: na | AS7: na | AT7: 44142 | AU7: na | AV7: 44158 | AZ7: 44523 | BC7: |
B8: =IF(D8=$A$516,1,IF(D8=$A$517,2,IF(D8=$A$518,3,IF(D8=$A$519,4,IF(D8=$A$520,5,IF(D8=$A$521,6)))))) -> 1 | D8: =IF(AL8="Closed","cls",IF(AL8=1,"sgn",IF(AL8="On-hold","hld",IF(AL8="Aborted","abt",IF(AL8<1,"wip","RIP"))))) -> cls | E8: Fra Diavolo (Pj Hell) | F8: Hell | G8: TO | H8: 01217560015 | I8: 642000 | J8: Food | K8: Catena di ristoranti pizzeria | L8: Mauro D'errico | S8: no | T8: 2020 | U8: 2.558 | V8: 0.127 | W8: 0.049648163 | X8: 0.005 | Y8: 1.739 | AA8: Relazione | AC8: LOM | AD8: LOM | AE8: RIM | AF8: LUS | AI8: =+TODAY()-AM8 -> 1215 | AJ8: =+(IF(AL8="Closed","-",IF(TODAY()-MAX(AN8:BA8)>0,TODAY()-MAX(AN8:BA8),0))) -> - | AK8: Sell Side | AL8: =+IF(BB8="",IF(AZ8="",IF(AY8="",IF(AX8="",COUNTA(AN8:AV8)/9,"On-hold"),"Aborted"),"Closed"),"RIP") -> Closed | AM8: 44449 | AN8: 44449 | AO8: 44449 | AP8: 44449 | AQ8: 44449 | AR8: na | AS8: na | AT8: 44453 | AU8: na | AV8: 44453 | AZ8: 44572 | BC8: |
B9: =IF(D9=$A$516,1,IF(D9=$A$517,2,IF(D9=$A$518,3,IF(D9=$A$519,4,IF(D9=$A$520,5,IF(D9=$A$521,6)))))) -> 1 | D9: =IF(AL9="Closed","cls",IF(AL9=1,"sgn",IF(AL9="On-hold","hld",IF(AL9="Aborted","abt",IF(AL9<1,"wip","RIP"))))) -> cls | E9: Bolaffi (Pj Mango) | F9: Mango | G9: TO | H9: 10156770017 | I9: 477700 | J9: Retail | K9: Commercio oro da investimento | L9: F. Bolaffi | S9: no | T9: 2019 | U9: 23.32 | V9: 0.77 | W9: 0.033018868 | X9: 0.52 | Y9: -0.1 | AA9: Relazione | AC9: LOM | AD9: ASC | AE9: PAD | AH9: 1 | AI9: =+TODAY()-AM9 -> 1347 | AJ9: =+(IF(AL9="Closed","-",IF(TODAY()-MAX(AN9:BA9)>0,TODAY()-MAX(AN9:BA9),0))) -> - | AK9: Buy Side | AL9: =+IF(BB9="",IF(AZ9="",IF(AY9="",IF(AX9="",COUNTA(AN9:AV9)/9,"On-hold"),"Aborted"),"Closed"),"RIP") -> Closed | AM9: 44317 | AN9: =+AM9 -> 44317 | AO9: na | AP9: na | AQ9: =+AN9 -> 44317 | AR9: na | AS9: na | AT9: na | AU9: na | AV9: 44376 | AZ9: 44530 | BC9: |
B10: =IF(D10=$A$516,1,IF(D10=$A$517,2,IF(D10=$A$518,3,IF(D10=$A$519,4,IF(D10=$A$520,5,IF(D10=$A$521,6)))))) -> 1 | D10: =IF(AL10="Closed","cls",IF(AL10=1,"sgn",IF(AL10="On-hold","hld",IF(AL10="Aborted","abt",IF(AL10<1,"wip","RIP"))))) -> cls | E10: P&B Melabimbi | G10: Francia | J10: Education | K10: Gestione di strutture scolastiche | L10: Odile Broglin | AA10: Relazione | AC10: LOM | AD10: LOM | AE10: LUS | AI10: =+TODAY()-AM10 -> 1292 | AJ10: =+(IF(AL10="Closed","-",IF(TODAY()-MAX(AN10:BA10)>0,TODAY()-MAX(AN10:BA10),0))) -> - | AK10: Buy Side | AL10: =+IF(BB10="",IF(AZ10="",IF(AY10="",IF(AX10="",COUNTA(AN10:AV10)/9,"On-hold"),"Aborted"),"Closed"),"RIP") -> Closed | AM10: 44372 | AN10: =+AM10 -> 44372 | AO10: na | AP10: na | AQ10: =+AN10 -> 44372 | AR10: na | AS10: na | AT10: na | AU10: na | AV10: na | AZ10: 44511 | BC10: |
B11: =IF(D11=$A$516,1,IF(D11=$A$517,2,IF(D11=$A$518,3,IF(D11=$A$519,4,IF(D11=$A$520,5,IF(D11=$A$521,6)))))) -> 1 | D11: =IF(AL11="Closed","cls",IF(AL11=1,"sgn",IF(AL11="On-hold","hld",IF(AL11="Aborted","abt",IF(AL11<1,"wip","RIP"))))) -> cls | E11: P&B Ristori | G11: Francia | J11: Education | K11: Gestione di strutture scolastiche | L11: Odile Broglin | AA11: Relazione | AC11: LOM | AD11: LOM | AE11: LUS | AI11: =+TODAY()-AM11 -> 1377 | AJ11: =+(IF(AL11="Closed","-",IF(TODAY()-MAX(AN11:BA11)>0,TODAY()-MAX(AN11:BA11),0))) -> - | AK11: Buy Side | AL11: =+IF(BB11="",IF(AZ11="",IF(AY11="",IF(AX11="",COUNTA(AN11:AV11)/9,"On-hold"),"Aborted"),"Closed"),"RIP") -> Closed | AM11: 44287 | AN11: =+AM11 -> 44287 | AO11: na | AP11: na | AQ11: =+AN11 -> 44287 | AR11: na | AS11: na | AT11: na | AU11: na | AV11: na | AZ11: 44491 | BC11: |
B12: =IF(D12=$A$516,1,IF(D12=$A$517,2,IF(D12=$A$518,3,IF(D12=$A$519,4,IF(D12=$A$520,5,IF(D12=$A$521,6)))))) -> 1 | D12: =IF(AL12="Closed","cls",IF(AL12=1,"sgn",IF(AL12="On-hold","hld",IF(AL12="Aborted","abt",IF(AL12<1,"wip","RIP"))))) -> cls | E12: Pezzutti Group (Valutazione) | F12: na | G12: PN | H12: 00300430931 | I12: 222909 | J12: Plastic | K12: Stampaggio materie plastiche a iniezione | L12: Fabio Messinese | M12: Fabio Messinese | S12: no | T12: 2019 | U12: 79.17 | V12: 6.97 | W12: 0.088038398 | X12: 2.24 | Y12: 40.34 | AA12: Segnalatore | AB12: Neri Andrea | AC12: ASC | AD12: ASC | AE12: PAD | AF12: LUS | AH12: 1 | AI12: =+TODAY()-AM12 -> 1408 | AJ12: =+(IF(AL12="Closed","-",IF(TODAY()-MAX(AN12:BA12)>0,TODAY()-MAX(AN12:BA12),0))) -> - | AK12: Valutazione | AL12: =+IF(BB12="",IF(AZ12="",IF(AY12="",IF(AX12="",COUNTA(AN12:AV12)/9,"On-hold"),"Aborted"),"Closed"),"RIP") -> Closed | AM12: 44256 | AN12: 44270 | AO12: na | AP12: 44294 | AQ12: 44294 | AR12: 44308 | AS12: 44342 | AT12: 44618 | AU12: 44630 | AV12: 44630 | AZ12: 44674 | BC12: |
B13: =IF(D13=$A$516,1,IF(D13=$A$517,2,IF(D13=$A$518,3,IF(D13=$A$519,4,IF(D13=$A$520,5,IF(D13=$A$521,6)))))) -> 1 | D13: =IF(AL13="Closed","cls",IF(AL13=1,"sgn",IF(AL13="On-hold","hld",IF(AL13="Aborted","abt",IF(AL13<1,"wip","RIP"))))) -> cls | E13: SoBeSport | G13: MI | H13: 08430980964 | I13: 829999 | J13: Other services | K13: Comunicazione e marketing sportivo per professionisti | L13: Gianluca Voulaz | M13: Gianluca Voulaz | S13: no | T13: 2019 | U13: 1.43 | V13: 0.3 | W13: 0.20979021 | X13: 0.2 | Y13: -0.32 | AA13: Relazione | AC13: ASC | AD13: ASC | AE13: LUS | AI13: =+TODAY()-AM13 -> 1177 | AJ13: =+(IF(AL13="Closed","-",IF(TODAY()-MAX(AN13:BA13)>0,TODAY()-MAX(AN13:BA13),0))) -> - | AK13: Sell Side | AL13: =+IF(BB13="",IF(AZ13="",IF(AY13="",IF(AX13="",COUNTA(AN13:AV13)/9,"On-hold"),"Aborted"),"Closed"),"RIP") -> Closed | AM13: 44487 | AN13: 44197 | AO13: na | AP13: 44197 | AQ13: 44197 | AR13: 44237 | AS13: 44270 | AT13: 44361 | AU13: 44461 | AV13: 44495 | AZ13: 44686 | BC13: |
B14: =IF(D14=$A$516,1,IF(D14=$A$517,2,IF(D14=$A$518,3,IF(D14=$A$519,4,IF(D14=$A$520,5,IF(D14=$A$521,6)))))) -> 1 | D14: =IF(AL14="Closed","cls",IF(AL14=1,"sgn",IF(AL14="On-hold","hld",IF(AL14="Aborted","abt",IF(AL14<1,"wip","RIP"))))) -> cls | E14: Rossi Navi (Valutazione) | F14: na | G14: LU | H14: 01431670460 | I14: 301000 | J14: Industrial | K14: Costruzione di navi e imbarcazioni | M14: Paride Rossi | N14: Claudio Rossi | S14: no | T14: 2019 | U14: 62.589 | V14: 1.646 | W14: 0.026298551 | X14: 0.17 | Y14: -2.066 | AA14: Relazione | AC14: ASC | AD14: ASC | AE14: PAD | AH14: 1 | AI14: =+TODAY()-AM14 -> 1256 | AJ14: =+(IF(AL14="Closed","-",IF(TODAY()-MAX(AN14:BA14)>0,TODAY()-MAX(AN14:BA14),0))) -> - | AK14: Valutazione | AL14: =+IF(BB14="",IF(AZ14="",IF(AY14="",IF(AX14="",COUNTA(AN14:AV14)/9,"On-hold"),"Aborted"),"Closed"),"RIP") -> Closed | AM14: 44408 | AN14: 44408 | AO14: na | AP14: na | AQ14: 44509 | AR14: na | AS14: 44609 | AT14: 44613 | AU14: 44620 | AV14: 44620 | AZ14: 44769 | BC14: |
B15: =IF(D15=$A$516,1,IF(D15=$A$517,2,IF(D15=$A$518,3,IF(D15=$A$519,4,IF(D15=$A$520,5,IF(D15=$A$521,6)))))) -> 1 | D15: =IF(AL15="Closed","cls",IF(AL15=1,"sgn",IF(AL15="On-hold","hld",IF(AL15="Aborted","abt",IF(AL15<1,"wip","RIP"))))) -> cls | E15: P&B Vispa Teresa | G15: Francia | J15: Education | K15: Gestione di strutture scolastiche | L15: Odile Broglin | AA15: Relazione | AC15: LOM | AD15: LOM | AE15: LUS | AI15: =+TODAY()-AM15 -> 1166 | AJ15: =+(IF(AL15="Closed","-",IF(TODAY()-MAX(AN15:BA15)>0,TODAY()-MAX(AN15:BA15),0))) -> - | AK15: Buy Side | AL15: =+IF(BB15="",IF(AZ15="",IF(AY15="",IF(AX15="",COUNTA(AN15:AV15)/9,"On-hold"),"Aborted"),"Closed"),"RIP") -> Closed | AM15: 44498 | AN15: =+AM15 -> 44498 | AO15: na | AP15: na | AQ15: =+AN15 -> 44498 | AR15: na | AS15: na | AT15: na | AU15: na | AV15: na | AZ15: 44916 | BC15: |
B16: =IF(D16=$A$516,1,IF(D16=$A$517,2,IF(D16=$A$518,3,IF(D16=$A$519,4,IF(D16=$A$520,5,IF(D16=$A$521,6)))))) -> 1 | D16: =IF(AL16="Closed","cls",IF(AL16=1,"sgn",IF(AL16="On-hold","hld",IF(AL16="Aborted","abt",IF(AL16<1,"wip","RIP"))))) -> cls | E16: P&B Canadian Island | G16: Francia | J16: Education | K16: Gestione di strutture scolastiche | L16: Odile Broglin | AA16: Relazione | AC16: LOM | AD16: LOM | AE16: LUS | AI16: =+TODAY()-AM16 -> 1216 | AJ16: =+(IF(AL16="Closed","-",IF(TODAY()-MAX(AN16:BA16)>0,TODAY()-MAX(AN16:BA16),0))) -> - | AK16: Buy Side | AL16: =+IF(BB16="",IF(AZ16="",IF(AY16="",IF(AX16="",COUNTA(AN16:AV16)/9,"On-hold"),"Aborted"),"Closed"),"RIP") -> Closed | AM16: 44448 | AN16: =+AM16 -> 44448 | AO16: na | AP16: na | AQ16: =+AN16 -> 44448 | AR16: na | AS16: na | AT16: na | AU16: na | AV16: na | AZ16: 44916 | BC16: |
B17: =IF(D17=$A$516,1,IF(D17=$A$517,2,IF(D17=$A$518,3,IF(D17=$A$519,4,IF(D17=$A$520,5,IF(D17=$A$521,6)))))) -> 1 | D17: =IF(AL17="Closed","cls",IF(AL17=1,"sgn",IF(AL17="On-hold","hld",IF(AL17="Aborted","abt",IF(AL17<1,"wip","RIP"))))) -> cls | E17: Pladway S.r.l. | G17: MI | H17: 10251710967 | I17: 731102 | J17: Tech | K17: Piattaforma di DOOH | L17: Luca Scelsa | S17: no | T17: 2022 | U17: 3.8 | V17: 0.006 | W17: 0.0015789474 | X17: na | Y17: na | AA17: Relazione | AC17: ASC | AD17: ASC | AE17: LUS | AG17: Intro Fee 10% | AI17: =+TODAY()-AM17 -> 820 | AJ17: =+(IF(AL17="Closed","-",IF(TODAY()-MAX(AN17:BA17)>0,TODAY()-MAX(AN17:BA17),0))) -> - | AK17: Sell Side | AL17: =+IF(BB17="",IF(AZ17="",IF(AY17="",IF(AX17="",COUNTA(AN17:AV17)/9,"On-hold"),"Aborted"),"Closed"),"RIP") -> Closed | AM17: 44844 | AN17: =+AM17 -> 44844 | AO17: na | AP17: 44849 | AQ17: 44849 | AR17: 44851 | AS17: na | AT17: 44852 | AU17: 44855 | AV17: 44858 | AZ17: 44985 | BC17: |
B18: =IF(D18=$A$516,1,IF(D18=$A$517,2,IF(D18=$A$518,3,IF(D18=$A$519,4,IF(D18=$A$520,5,IF(D18=$A$521,6)))))) -> 1 | D18: =IF(AL18="Closed","cls",IF(AL18=1,"sgn",IF(AL18="On-hold","hld",IF(AL18="Aborted","abt",IF(AL18<1,"wip","RIP"))))) -> cls | E18: Becoming Education (buy OIS) | F18: Nido | G18: MI | H18: 11603690964 | I18: 889100 | J18: Education | K18: Gestione di strutture scolastiche | AA18: Relazione | AC18: LOM | AD18: LOM | AE18: LUS | AI18: =+TODAY()-AM18 -> 1023 | AJ18: =+(IF(AL18="Closed","-",IF(TODAY()-MAX(AN18:BA18)>0,TODAY()-MAX(AN18:BA18),0))) -> - | AK18: Buy Side | AL18: =+IF(BB18="",IF(AZ18="",IF(AY18="",IF(AX18="",COUNTA(AN18:AV18)/9,"On-hold"),"Aborted"),"Closed"),"RIP") -> Closed | AM18: 44641 | AN18: 44641 | AO18: na | AP18: na | AQ18: 44651 | AR18: 44662 | AS18: na | AT18: na | AU18: na | AV18: 44677 | AZ18: 44957 | BC18: |
B19: =IF(D19=$A$516,1,IF(D19=$A$517,2,IF(D19=$A$518,3,IF(D19=$A$519,4,IF(D19=$A$520,5,IF(D19=$A$521,6)))))) -> 1 | D19: =IF(AL19="Closed","cls",IF(AL19=1,"sgn",IF(AL19="On-hold","hld",IF(AL19="Aborted","abt",IF(AL19<1,"wip","RIP"))))) -> cls | E19: Rossi Navi (M&A) | F19: Penta | G19: LU | H19: 01431670460 | I19: 301000 | J19: Industrial | K19: Costruzione di navi e imbarcazioni | M19: Paride Rossi | N19: Claudio Rossi | S19: no | T19: 2019 | U19: 62.589 | V19: 1.646 | W19: 0.026298551 | X19: 0.17 | Y19: -2.066 | AA19: Relazione | AC19: ASC | AD19: ASC | AE19: PAD | AF19: GID | AH19: 1 | AI19: =+TODAY()-AM19 -> 891 | AJ19: =+(IF(AL19="Closed","-",IF(TODAY()-MAX(AN19:BA19)>0,TODAY()-MAX(AN19:BA19),0))) -> - | AK19: Valutazione | AL19: =+IF(BB19="",IF(AZ19="",IF(AY19="",IF(AX19="",COUNTA(AN19:AV19)/9,"On-hold"),"Aborted"),"Closed"),"RIP") -> Closed | AM19: 44773 | AN19: 44408 | AO19: na | AP19: na | AQ19: 44896 | AR19: na | AS19: na | AT19: na | AU19: na | AV19: 45029 | AZ19: 45086 | BC19: |
B20: =IF(D20=$A$516,1,IF(D20=$A$517,2,IF(D20=$A$518,3,IF(D20=$A$519,4,IF(D20=$A$520,5,IF(D20=$A$521,6)))))) -> 1 | D20: =IF(AL20="Closed","cls",IF(AL20=1,"sgn",IF(AL20="On-hold","hld",IF(AL20="Aborted","abt",IF(AL20<1,"wip","RIP"))))) -> cls | E20: Seatram (Valutazione) | G20: GE | H20: 02806090102 | I20: 522910 | J20: Logistics | K20: Freight Forwarding | L20: L. Bruzzo | S20: no | T20: 2019 | U20: 29.07 | V20: 2.25 | W20: 0.077399381 | X20: 1.51 | Y20: -0.21 | AA20: Relazione | AC20: ASC | AD20: ASC | AE20: LUS | AF20: GID | AI20: =+TODAY()-AM20 -> 1422 | AJ20: =+(IF(AL20="Closed","-",IF(TODAY()-MAX(AN20:BA20)>0,TODAY()-MAX(AN20:BA20),0))) -> - | AK20: Valutazione | AL20: =+IF(BB20="",IF(AZ20="",IF(AY20="",IF(AX20="",COUNTA(AN20:AV20)/9,"On-hold"),"Aborted"),"Closed"),"RIP") -> Closed | AM20: 44242 | AN20: 44242 | AO20: na | AP20: 44242 | AQ20: 44249 | AR20: 44305 | AS20: 44985 | AT20: 45023 | AU20: na | AV20: 45043 | AZ20: 45174 | BC20: |
B21: =IF(D21=$A$516,1,IF(D21=$A$517,2,IF(D21=$A$518,3,IF(D21=$A$519,4,IF(D21=$A$520,5,IF(D21=$A$521,6)))))) -> 1 | D21: =IF(AL21="Closed","cls",IF(AL21=1,"sgn",IF(AL21="On-hold","hld",IF(AL21="Aborted","abt",IF(AL21<1,"wip","RIP"))))) -> cls | E21: English Gate School (sell side) | F21: Idia | G21: CO | H21: 07055650969 | I21: 889100 | J21: Education | K21: Gestione di strutture scolastiche | L21: Klodia Gaudino | S21: no | T21: 2020 | U21: 1.084 | V21: 0.085 | W21: 0.078413284 | X21: -0.065 | Y21: -0.561 | AA21: Cold Call | AC21: LOM | AD21: LOM | AE21: LUS | AI21: =+TODAY()-AM21 -> 963 | AJ21: =+(IF(AL21="Closed","-",IF(TODAY()-MAX(AN21:BA21)>0,TODAY()-MAX(AN21:BA21),0))) -> - | AK21: Sell Side | AL21: =+IF(BB21="",IF(AZ21="",IF(AY21="",IF(AX21="",COUNTA(AN21:AV21)/9,"On-hold"),"Aborted"),"Closed"),"RIP") -> Closed | AM21: 44701 | AN21: 44701 | AO21: na | AP21: 44704 | AQ21: 44707 | AR21: na | AS21: 44727 | AT21: 44741 | AU21: 44771 | AV21: 44777 | AZ21: 45209 | BC21: |
B22: =IF(D22=$A$516,1,IF(D22=$A$517,2,IF(D22=$A$518,3,IF(D22=$A$519,4,IF(D22=$A$520,5,IF(D22=$A$521,6)))))) -> 1 | D22: =IF(AL22="Closed","cls",IF(AL22=1,"sgn",IF(AL22="On-hold","hld",IF(AL22="Aborted","abt",IF(AL22<1,"wip","RIP"))))) -> cls | E22: YIES School | F22: Cedar | G22: MB | H22: 09365500967 | I22: 852000 | J22: Education | K22: Gestione di strutture scolastiche | L22: Angela Paladino | S22: no | T22: 2021 | U22: 0.846 | V22: 0.083 | W22: 0.098108747 | X22: 0.031 | Y22: -0.246 | AA22: Cold Call | AC22: LOM | AD22: LOM | AE22: LUS | AF22: GID | AI22: =+TODAY()-AM22 -> 963 | AJ22: =+(IF(AL22="Closed","-",IF(TODAY()-MAX(AN22:BA22)>0,TODAY()-MAX(AN22:BA22),0))) -> - | AK22: Sell Side | AL22: =+IF(BB22="",IF(AZ22="",IF(AY22="",IF(AX22="",COUNTA(AN22:AV22)/9,"On-hold"),"Aborted"),"Closed"),"RIP") -> Closed | AM22: 44701 | AN22: 44701 | AO22: na | AP22: 44701 | AQ22: 44707 | AR22: 44819 | AS22: 44851 | AT22: 44853 | AU22: 44963 | AV22: 44992 | AZ22: 45278 | BC22: |
B23: =IF(D23=$A$516,1,IF(D23=$A$517,2,IF(D23=$A$518,3,IF(D23=$A$519,4,IF(D23=$A$520,5,IF(D23=$A$521,6)))))) -> 1 | D23: =IF(AL23="Closed","cls",IF(AL23=1,"sgn",IF(AL23="On-hold","hld",IF(AL23="Aborted","abt",IF(AL23<1,"wip","RIP"))))) -> cls | E23: F.A.S.T. | F23: Race | G23: RA | H23: 01120890395 | J23: Other services | K23: Agenzia di viaggi | L23: Massimo Bertozzi | S23: no | T23: 2020 | U23: 4.844 | V23: 0.693 | W23: 0.14306358 | X23: 0.591 | Y23: n.d. | AA23: Azionista | AB23: Maurizio Bertozzi | AC23: ASC | AD23: ASC | AE23: GID | AI23: =+TODAY()-AM23 -> 810 | AJ23: =+(IF(AL23="Closed","-",IF(TODAY()-MAX(AN23:BA23)>0,TODAY()-MAX(AN23:BA23),0))) -> - | AK23: Sell Side | AL23: =+IF(BB23="",IF(AZ23="",IF(AY23="",IF(AX23="",COUNTA(AN23:AV23)/9,"On-hold"),"Aborted"),"Closed"),"RIP") -> Closed | AM23: 44854 | AN23: 44854 | AO23: na | AP23: 44854 | AQ23: 44854 | AR23: 44861 | AS23: 44867 | AT23: 44881 | AU23: 44897 | AV23: 44938 | AW23: =TODAY() -> 45664 | AZ23: 45260 | BC23: |
B24: =IF(D24=$A$516,1,IF(D24=$A$517,2,IF(D24=$A$518,3,IF(D24=$A$519,4,IF(D24=$A$520,5,IF(D24=$A$521,6)))))) -> 1 | D24: =IF(AL24="Closed","cls",IF(AL24=1,"sgn",IF(AL24="On-hold","hld",IF(AL24="Aborted","abt",IF(AL24<1,"wip","RIP"))))) -> cls | E24: Eurocert SpA | F24: Assure | G24: BO | J24: Servizi Certificazione | K24: Azienda di certificazione tecnica di impianti civili di vario genere | L24: Andrea Ballandi | S24: no | T24: 2022 | U24: 13.298 | V24: 1.76 | W24: =+V24/U24 -> 0.13235073 | X24: 0.945 | Y24: -4.986 | AA24: Segnalatore | AB24: Andrea Lenzi | AC24: FCA | AD24: FCA | AI24: =+TODAY()-AM24 -> 606 | AJ24: =+(IF(AL24="Closed","-",IF(TODAY()-MAX(AN24:BA24)>0,TODAY()-MAX(AN24:BA24),0))) -> - | AK24: Buy Side | AL24: =+IF(BB24="",IF(AZ24="",IF(AY24="",IF(AX24="",COUNTA(AN24:AV24)/9,"On-hold"),"Aborted"),"Closed"),"RIP") -> Closed | AM24: 45058 | AN24: 45058 | AO24: na | AP24: 45058 | AQ24: 45058 | AR24: 45077 | AS24: na | AT24: na | AU24: na | AV24: 45117 | AW24: =TODAY() -> 45664 | AZ24: 45327 | BC24: |
B25: =IF(D25=$A$516,1,IF(D25=$A$517,2,IF(D25=$A$518,3,IF(D25=$A$519,4,IF(D25=$A$520,5,IF(D25=$A$521,6)))))) -> 1 | D25: =IF(AL25="Closed","cls",IF(AL25=1,"sgn",IF(AL25="On-hold","hld",IF(AL25="Aborted","abt",IF(AL25<1,"wip","RIP"))))) -> cls | E25: Fra Diavolo (2° round) | G25: TO | H25: 00767700156 | I25: 642000 | J25: Food | K25: Catena di ristoranti pizzeria | L25: Mauro D'errico | S25: no | T25: 2020 | U25: 2.558 | V25: 0.127 | W25: =+V25/U25 -> 0.049648163 | X25: 0.005 | Y25: 1.739 | AA25: Relazione | AC25: LOM | AD25: LOM | AE25: PAD | AF25: GID | AG25: Buy Alto Partners | AI25: =+TODAY()-AM25 -> 1215 | AJ25: =+(IF(AL25="Closed","-",IF(TODAY()-MAX(AN25:BA25)>0,TODAY()-MAX(AN25:BA25),0))) -> - | AK25: Buy Side | AL25: =+IF(BB25="",IF(AZ25="",IF(AY25="",IF(AX25="",COUNTA(AN25:AV25)/9,"On-hold"),"Aborted"),"Closed"),"RIP") -> Closed | AM25: 44449 | AN25: 44449 | AO25: 44449 | AP25: 44449 | AQ25: 44449 | AR25: na | AS25: 45236 | AT25: 45245 | AU25: 45320 | AV25: 45320 | AW25: =TODAY() -> 45664 | AZ25: 45433 | BC25: |
B26: =IF(D26=$A$516,1,IF(D26=$A$517,2,IF(D26=$A$518,3,IF(D26=$A$519,4,IF(D26=$A$520,5,IF(D26=$A$521,6)))))) -> 1 | D26: =IF(AL26="Closed","cls",IF(AL26=1,"sgn",IF(AL26="On-hold","hld",IF(AL26="Aborted","abt",IF(AL26<1,"wip","RIP"))))) -> cls | E26: Ferrari - Contratto di Sviluppo (CdS) | F26: e-Building | G26: MO | H26: 00159560366 | J26: Automotive | K26: Produzione auto sportive | L26: Alessandro Tedesco | M26: Ferrari N.V | O26: John Philip Elkann | P26: Benedetto Vigna | Q26: Ignazio Carbone | S26: no | T26: 2023 | U26: 5650 | V26: 1792.321 | W26: =+V26/U26 -> 0.31722496 | X26: 1275 | Y26: -0.841 | AA26: Segnalatore | AB26: Aimo + Consulman | AC26: FCA | AD26: FCA | AE26: MMO | AF26: GSE | AI26: =+TODAY()-AM26 -> 1651 | AJ26: =+(IF(AL26="Closed","-",IF(TODAY()-MAX(AN26:BA26)>0,TODAY()-MAX(AN26:BA26),0))) -> - | AK26: Agevolato | AL26: =+IF(BB26="",IF(AZ26="",IF(AY26="",IF(AX26="",COUNTA(AN26:AV26)/9,"On-hold"),"Aborted"),"Closed"),"RIP") -> Closed | AM26: 44013 | AN26: 44013 | AO26: na | AP26: 44075 | AQ26: 44075 | AR26: 44103 | AS26: 44105 | AT26: 44105 | AU26: na | AV26: 44159 | AW26: =TODAY() -> 45664 | AZ26: 45502 | BC26: |
B27: =IF(D27=$A$516,1,IF(D27=$A$517,2,IF(D27=$A$518,3,IF(D27=$A$519,4,IF(D27=$A$520,5,IF(D27=$A$521,6)))))) -> 1 | D27: =IF(AL27="Closed","cls",IF(AL27=1,"sgn",IF(AL27="On-hold","hld",IF(AL27="Aborted","abt",IF(AL27<1,"wip","RIP"))))) -> cls | E27: International School Brescia (sell side) | F27: Garda | G27: BS | H27: 03915470987 | I27: 852000 | J27: Education | K27: Scuola internazionale k-12 | L27: Omar Bonomelli | M27: Sunderland Srl | N27: Barbara Filippini | P27: Omar Bonomelli | S27: no | T27: 2023 | U27: 2.685 | V27: 0.585 | W27: =+V27/U27 -> 0.21787709 | X27: 0 | Y27: 0 | AA27: Cold Call | AC27: LOM | AD27: LOM | AE27: LUS | AF27: GID | AI27: =+TODAY()-AM27 -> 770 | AJ27: =+(IF(AL27="Closed","-",IF(TODAY()-MAX(AN27:BA27)>0,TODAY()-MAX(AN27:BA27),0))) -> - | AK27: Sell Side | AL27: =+IF(BB27="",IF(AZ27="",IF(AY27="",IF(AX27="",COUNTA(AN27:AV27)/9,"On-hold"),"Aborted"),"Closed"),"RIP") -> Closed | AM27: 44894 | AN27: 44894 | AO27: na | AP27: 44895 | AQ27: 44951 | AR27: 45014 | AS27: 45084 | AT27: 45131 | AU27: 45139 | AV27: 45147 | AW27: =TODAY() -> 45664 | AZ27: 45477 | BC27: |
B28: =IF(D28=$A$516,1,IF(D28=$A$517,2,IF(D28=$A$518,3,IF(D28=$A$519,4,IF(D28=$A$520,5,IF(D28=$A$521,6)))))) -> 1 | D28: =IF(AL28="Closed","cls",IF(AL28=1,"sgn",IF(AL28="On-hold","hld",IF(AL28="Aborted","abt",IF(AL28<1,"wip","RIP"))))) -> cls | E28: Maschio Gaspardo - Simest | F28: Internaz. | G28: PD | H28: 03272800289 | I28: 283090 | J28: Industrial | K28: Produzione attrezzature agricole | L28: Pierantonio Prevarin | M28: Maschio Holding Spa | N28: Self owned | O28: Mirco Maschio | P28: Luigi De Puppi | Q28: Pietro Del Fabbro | S28: no | T28: 2023 | U28: 425.13 | V28: 64.202 | W28: =+V28/U28 -> 0.15101734 | X28: 25.631 | Y28: 116.723 | AA28: Segnalatore | AB28: Mise | AC28: FCA | AD28: FCA | AE28: MMO | AF28: GSE | AI28: =+TODAY()-AM28 -> 556 | AJ28: =+(IF(AL28="Closed","-",IF(TODAY()-MAX(AN28:BA28)>0,TODAY()-MAX(AN28:BA28),0))) -> - | AK28: Agevolato | AL28: =+IF(BB28="",IF(AZ28="",IF(AY28="",IF(AX28="",COUNTA(AN28:AV28)/9,"On-hold"),"Aborted"),"Closed"),"RIP") -> Closed | AM28: 45108 | AN28: =+AM28 -> 45108 | AO28: na | AP28: na | AQ28: =+AN28 -> 45108 | AR28: na | AS28: na | AT28: na | AU28: na | AV28: 44859 | AW28: =TODAY() -> 45664 | AZ28: 45614 | BC28: |
B29: =IF(D29=$A$516,1,IF(D29=$A$517,2,IF(D29=$A$518,3,IF(D29=$A$519,4,IF(D29=$A$520,5,IF(D29=$A$521,6)))))) -> 2 | C29: =+COUNTIF(D:D,"sgn") -> 7 | D29: =IF(AL29="Closed","cls",IF(AL29=1,"sgn",IF(AL29="On-hold","hld",IF(AL29="Aborted","abt",IF(AL29<1,"wip","RIP"))))) -> sgn | E29: ISL Nardi | F29: Edvige | G29: MI | H29: 11878560157 | I29: 522921 | J29: Logistics | K29: Spedizioni internazionali via nave | M29: Andrea Gay | N29: Stefano Guazzaroni | O29: Andrea Gay | Q29: Emanuele Borgonovo | S29: si | T29: 2022 | U29: 87.778 | V29: 2.848 | W29: =+V29/U29 -> 0.032445487 | X29: 1.921 | Y29: -6.213 | AA29: Relazione | AC29: ASC | AD29: ASC | AE29: RIM | AF29: LUS | AI29: =+TODAY()-AM29 -> 1166 | AJ29: =+(IF(AL29="Closed","-",IF(TODAY()-MAX(AN29:BA29)>0,TODAY()-MAX(AN29:BA29),0))) -> 0 | AK29: Sell Side | AL29: =+IF(BB29="",IF(AZ29="",IF(AY29="",IF(AX29="",COUNTA(AN29:AV29)/9,"On-hold"),"Aborted"),"Closed"),"RIP") -> 1 | AM29: 44498 | AN29: 44498 | AO29: na | AP29: 44498 | AQ29: 44510 | AR29: 44524 | AS29: na | AT29: 44540 | AU29: 44588 | AV29: 44588 | AW29: =TODAY() -> 45664 | BC29: |
B30: =IF(D30=$A$516,1,IF(D30=$A$517,2,IF(D30=$A$518,3,IF(D30=$A$519,4,IF(D30=$A$520,5,IF(D30=$A$521,6)))))) -> 2 | D30: =IF(AL30="Closed","cls",IF(AL30=1,"sgn",IF(AL30="On-hold","hld",IF(AL30="Aborted","abt",IF(AL30<1,"wip","RIP"))))) -> sgn | E30: Fischer & Rechsteiner (buy) | G30: LC | H30: 00210750139 | I30: 522910 | J30: Logistics | K30: Spedizioni internazionali via nave | L30: Riccardo Riva | M30: Inter Freight | P30: Riccardo Riva | Q30: Luigi Frizzi | S30: no | T30: 2023 | U30: 27.284 | V30: 0.452 | W30: =+V30/U30 -> 0.016566486 | X30: 0.266 | Y30: 2.223 | AA30: Segnalatore | AB30: Ermanno Restano | AC30: ASC | AD30: ASC | AE30: RIM | AF30: GID | AI30: =+TODAY()-AM30 -> 522 | AJ30: =+(IF(AL30="Closed","-",IF(TODAY()-MAX(AN30:BA30)>0,TODAY()-MAX(AN30:BA30),0))) -> 0 | AK30: Buy Side | AL30: =+IF(BB30="",IF(AZ30="",IF(AY30="",IF(AX30="",COUNTA(AN30:AV30)/9,"On-hold"),"Aborted"),"Closed"),"RIP") -> 1 | AM30: 45142 | AN30: 45142 | AO30: 45142 | AP30: 45142 | AQ30: =+AN30 -> 45142 | AR30: na | AS30: 45181 | AT30: 45217 | AU30: na | AV30: 45229 | AW30: =TODAY() -> 45664 | BC30: |
B31: =IF(D31=$A$516,1,IF(D31=$A$517,2,IF(D31=$A$518,3,IF(D31=$A$519,4,IF(D31=$A$520,5,IF(D31=$A$521,6)))))) -> 2 | D31: =IF(AL31="Closed","cls",IF(AL31=1,"sgn",IF(AL31="On-hold","hld",IF(AL31="Aborted","abt",IF(AL31<1,"wip","RIP"))))) -> sgn | E31: Haier/Candy - Contratto di Sviluppo (CdS) | F31: Digit+Sost | G31: MB | H31: 00786860965 | J31: Industrial | K31: Produzione elettrodomestici | L31: Daniele Frigerio | M31: Haier | O31: Neil Tunstall | P31: Neill Tunstall | S31: no | T31: 2022 | U31: 1192 | V31: -15.08 | W31: =+V31/U31 -> -0.012651007 | X31: -163 | Y31: 289.797 | AA31: Segnalatore | AB31: Consulman | AC31: FCA | AD31: FCA | AE31: MMO | AF31: GSE | AI31: =+TODAY()-AM31 -> 1286 | AJ31: =+(IF(AL31="Closed","-",IF(TODAY()-MAX(AN31:BA31)>0,TODAY()-MAX(AN31:BA31),0))) -> 0 | AK31: Agevolato | AL31: =+IF(BB31="",IF(AZ31="",IF(AY31="",IF(AX31="",COUNTA(AN31:AV31)/9,"On-hold"),"Aborted"),"Closed"),"RIP") -> 1 | AM31: 44378 | AN31: =+AM31 -> 44378 | AO31: na | AP31: na | AQ31: =+AN31 -> 44378 | AR31: na | AS31: na | AT31: na | AU31: na | AV31: 44644 | AW31: =TODAY() -> 45664 | BC31: |
B32: =IF(D32=$A$516,1,IF(D32=$A$517,2,IF(D32=$A$518,3,IF(D32=$A$519,4,IF(D32=$A$520,5,IF(D32=$A$521,6)))))) -> 2 | D32: =IF(AL32="Closed","cls",IF(AL32=1,"sgn",IF(AL32="On-hold","hld",IF(AL32="Aborted","abt",IF(AL32<1,"wip","RIP"))))) -> sgn | E32: Ferrari - CdS - Management & Reporting | F32: e-Building | G32: MO | H32: 00159560366 | J32: Automotive | K32: Produzione auto sportive | L32: Alessandro Tedesco | M32: Ferrari N.V | O32: John Philip Elkann | P32: Benedetto Vigna | Q32: Ignazio Carbone | S32: no | T32: 2023 | U32: 5650 | V32: 1792.3 | W32: =+V32/U32 -> 0.31722124 | X32: 1275 | Y32: -0.8 | AA32: Segnalatore | AB32: Aimo + Consulman | AC32: FCA | AD32: FCA | AE32: GSE | AF32: MMO | AI32: =+TODAY()-AM32 -> 859 | AJ32: =+(IF(AL32="Closed","-",IF(TODAY()-MAX(AN32:BA32)>0,TODAY()-MAX(AN32:BA32),0))) -> 0 | AK32: Agevolato | AL32: =+IF(BB32="",IF(AZ32="",IF(AY32="",IF(AX32="",COUNTA(AN32:AV32)/9,"On-hold"),"Aborted"),"Closed"),"RIP") -> 1 | AM32: 44805 | AN32: =+AM32 -> 44805 | AO32: na | AP32: na | AQ32: =+AN32 -> 44805 | AR32: na | AS32: na | AT32: na | AU32: na | AV32: 44872 | AW32: =TODAY() -> 45664 | BC32: |
B33: =IF(D33=$A$516,1,IF(D33=$A$517,2,IF(D33=$A$518,3,IF(D33=$A$519,4,IF(D33=$A$520,5,IF(D33=$A$521,6)))))) -> 2 | D33: =IF(AL33="Closed","cls",IF(AL33=1,"sgn",IF(AL33="On-hold","hld",IF(AL33="Aborted","abt",IF(AL33<1,"wip","RIP"))))) -> sgn | E33: Myes School (sellside) | F33: Anfield | G33: FI | H33: 07096960484 | J33: Education | K33: Corsi di lingua | M33: Myes Firenze Srl | P33: Luigi Sguerri | S33: no | T33: 2023 | U33: 5.035 | V33: 0.226 | W33: =+V33/U33 -> 0.044885799 | X33: 0.103 | Y33: -0.014 | AA33: Cold Call | AC33: LOM | AD33: LOM | AE33: LUS | AF33: GID | AI33: =+TODAY()-AM33 -> 749 | AJ33: =+(IF(AL33="Closed","-",IF(TODAY()-MAX(AN33:BA33)>0,TODAY()-MAX(AN33:BA33),0))) -> 0 | AK33: Sell Side | AL33: =+IF(BB33="",IF(AZ33="",IF(AY33="",IF(AX33="",COUNTA(AN33:AV33)/9,"On-hold"),"Aborted"),"Closed"),"RIP") -> 1 | AM33: 44915 | AN33: 45013 | AO33: na | AP33: 45062 | AQ33: 45069 | AR33: 45113 | AS33: 45124 | AT33: 45344 | AU33: na | AV33: 45350 | AW33: =TODAY() -> 45664 | BA33: =+IF(AY33="","",COUNTA(AN33:AV33)/(COUNTA(AN33:AV33)+COUNTBLANK(AN33:AV33))) | BC33: |
B34: =IF(D34=$A$516,1,IF(D34=$A$517,2,IF(D34=$A$518,3,IF(D34=$A$519,4,IF(D34=$A$520,5,IF(D34=$A$521,6)))))) -> 2 | D34: =IF(AL34="Closed","cls",IF(AL34=1,"sgn",IF(AL34="On-hold","hld",IF(AL34="Aborted","abt",IF(AL34<1,"wip","RIP"))))) -> sgn | E34: Kilometro Verde | F34: Mars | G34: BS | H34: 04267900985 | J34: Food | K34: Vertical farms | L34: Battagliola | P34: Sabrina De Filippis | S34: no | T34: 2023 | U34: 0.06 | V34: -1.421 | W34: =+V34/U34 -> -23.683333 | X34: -2.347 | Y34: 13.203 | AA34: Azionista | AB34: Dario Micheli | AC34: ROS | AD34: ROS | AE34: PAD | AF34: GID | AH34: 1 | AI34: =+TODAY()-AM34 -> 235 | AJ34: =+(IF(AL34="Closed","-",IF(TODAY()-MAX(AN34:BA34)>0,TODAY()-MAX(AN34:BA34),0))) -> 0 | AK34: Fundraising | AL34: =+IF(BB34="",IF(AZ34="",IF(AY34="",IF(AX34="",COUNTA(AN34:AV34)/9,"On-hold"),"Aborted"),"Closed"),"RIP") -> 1 | AM34: 45429 | AN34: 45429 | AO34: 45429 | AP34: 45429 | AQ34: 45429 | AR34: 45436 | AS34: 45436 | AT34: 45439 | AU34: 45441 | AV34: 45441 | AW34: =TODAY() -> 45664 | BC34: |
B35: =IF(D35=$A$516,1,IF(D35=$A$517,2,IF(D35=$A$518,3,IF(D35=$A$519,4,IF(D35=$A$520,5,IF(D35=$A$521,6)))))) -> 2 | D35: =IF(AL35="Closed","cls",IF(AL35=1,"sgn",IF(AL35="On-hold","hld",IF(AL35="Aborted","abt",IF(AL35<1,"wip","RIP"))))) -> sgn | E35: Formazione Giuridica | F35: Edera | G35: BO | H35: 03266791205 | J35: Education | K35: Corsi di preparazione a esami di avvocatura, magistratura, notariato | L35: Marco Zincani | S35: no | T35: 2022 | U35: 1.84 | V35: 0.883 | W35: =+V35/U35 -> 0.4798913 | X35: 0.507 | Y35: n.d. | AA35: Cold Call | AC35: LUS | AD35: LOM | AE35: LUS | AF35: GID | AI35: =+TODAY()-AM35 -> 195 | AJ35: =+(IF(AL35="Closed","-",IF(TODAY()-MAX(AN35:BA35)>0,TODAY()-MAX(AN35:BA35),0))) -> 0 | AK35: Sell Side | AL35: =+IF(BB35="",IF(AZ35="",IF(AY35="",IF(AX35="",COUNTA(AN35:AV35)/9,"On-hold"),"Aborted"),"Closed"),"RIP") -> 1 | AM35: 45469 | AN35: 45470 | AO35: na | AP35: 45470 | AQ35: 45476 | AR35: na | AS35: 45481 | AT35: 45489 | AU35: 45498 | AV35: 45499 | AW35: =+TODAY() -> 45664 | BC35: |
B36: =IF(D36=$A$516,1,IF(D36=$A$517,2,IF(D36=$A$518,3,IF(D36=$A$519,4,IF(D36=$A$520,5,IF(D36=$A$521,6)))))) -> 3 | D36: =IF(AL36="Closed","cls",IF(AL36=1,"sgn",IF(AL36="On-hold","hld",IF(AL36="Aborted","abt",IF(AL36<1,"wip","RIP"))))) -> wip | E36: Distilleria F.lli Caffo (Buy-side_2025) | G36: VV | H36: 08575640969 | I36: 110100 | J36: Food: Spirits | K36: Distilleria - Amaro del Capo | L36: Sabastiano Caffo | M36: Fam. Caffo | N36: Giuseppe Giovanni Caffo | P36: Sebastiano Giovanni Caffo | Q36: Lorenzo Pagliuca | S36: sì | T36: 2022 | U36: 93 | V36: 22 | W36: =+V36/U36 -> 0.23655914 | X36: 11.8 | Y36: -13 | AA36: Relazione | AC36: ASC | AD36: ASC | AE36: RIM | AF36: LUS | AI36: =+TODAY()-AM36 -> 1528 | AJ36: =+(IF(AL36="Closed","-",IF(TODAY()-MAX(AN36:BA36)>0,TODAY()-MAX(AN36:BA36),0))) -> 18 | AK36: Buy Side | AL36: =+IF(BB36="",IF(AZ36="",IF(AY36="",IF(AX36="",COUNTA(AN36:AV36)/9,"On-hold"),"Aborted"),"Closed"),"RIP") -> 0.88888889 | AM36: 44136 | AN36: 44136 | AO36: na | AP36: 44136 | AQ36: 45631 | AR36: na | AS36: na | AT36: 45636 | AU36: 45646 | AW36: 45646 | BC36: |
B37: =IF(D37=$A$516,1,IF(D37=$A$517,2,IF(D37=$A$518,3,IF(D37=$A$519,4,IF(D37=$A$520,5,IF(D37=$A$521,6)))))) -> 3 | D37: =IF(AL37="Closed","cls",IF(AL37=1,"sgn",IF(AL37="On-hold","hld",IF(AL37="Aborted","abt",IF(AL37<1,"wip","RIP"))))) -> wip | E37: Fagioli PFW | G37: RE | H37: 00674300355 | J37: Logistics | K37: Project Cargo - freight forwarding | M37: Quattro R | S37: no | T37: 2022 | U37: 32 | V37: 4.503 | W37: =+V37/U37 -> 0.14071875 | X37: 2.26 | Y37: 46.553 | AA37: Relazione | AC37: ASC | AD37: ASC | AE37: RIM | AF37: SEB | AI37: =+TODAY()-AM37 -> 242 | AJ37: =+(IF(AL37="Closed","-",IF(TODAY()-MAX(AN37:BA37)>0,TODAY()-MAX(AN37:BA37),0))) -> 36 | AK37: Sell Side | AL37: =+IF(BB37="",IF(AZ37="",IF(AY37="",IF(AX37="",COUNTA(AN37:AV37)/9,"On-hold"),"Aborted"),"Closed"),"RIP") -> 0.66666667 | AM37: 45422 | AN37: 45422 | AO37: 45422 | AP37: 45422 | AQ37: 45432 | AR37: 45471 | AS37: 45628 | AW37: 45628 | BC37: |
B38: =IF(D38=$A$516,1,IF(D38=$A$517,2,IF(D38=$A$518,3,IF(D38=$A$519,4,IF(D38=$A$520,5,IF(D38=$A$521,6)))))) -> 3 | D38: =IF(AL38="Closed","cls",IF(AL38=1,"sgn",IF(AL38="On-hold","hld",IF(AL38="Aborted","abt",IF(AL38<1,"wip","RIP"))))) -> wip | E38: Gemarmed | F38: Apollo | G38: MO | J38: Pharma | K38: Consulenza nella certificazione di medical devices | L38: Mario Gennari | S38: no | AA38: Segnalatore | AB38: GMAP | AC38: ASC | AD38: ASC | AE38: PAD | AH38: 1 | AI38: =+TODAY()-AM38 -> 333 | AJ38: =+(IF(AL38="Closed","-",IF(TODAY()-MAX(AN38:BA38)>0,TODAY()-MAX(AN38:BA38),0))) -> 288 | AK38: Buy Side | AL38: =+IF(BB38="",IF(AZ38="",IF(AY38="",IF(AX38="",COUNTA(AN38:AV38)/9,"On-hold"),"Aborted"),"Closed"),"RIP") -> 0.55555556 | AM38: 45331 | AN38: 45331 | AO38: na | AP38: 45335 | AQ38: 45335 | AR38: 45376 | BC38: |
B39: =IF(D39=$A$516,1,IF(D39=$A$517,2,IF(D39=$A$518,3,IF(D39=$A$519,4,IF(D39=$A$520,5,IF(D39=$A$521,6)))))) -> 3 | D39: =IF(AL39="Closed","cls",IF(AL39=1,"sgn",IF(AL39="On-hold","hld",IF(AL39="Aborted","abt",IF(AL39<1,"wip","RIP"))))) -> wip | E39: Weerts Logistics Parks (WLP) | G39: Belgio | J39: Logistics | K39: Sviluppo e gestione di immobili logistici di alto livello in Europa | L39: Othmane Sabere | P39: Christophe Weerts | S39: no | T39: 2023 | W39: =+V39/U39 -> #DIV/0! | AA39: Segnalatore | AB39: Ivano Pelassa | AC39: FCA | AD39: FCA | AE39: MMO | AG39: ZES unica Sud-Bari | AI39: =+TODAY()-AM39 -> 57 | AJ39: =+(IF(AL39="Closed","-",IF(TODAY()-MAX(AN39:BA39)>0,TODAY()-MAX(AN39:BA39),0))) -> 57 | AK39: Agevolato | AL39: =+IF(BB39="",IF(AZ39="",IF(AY39="",IF(AX39="",COUNTA(AN39:AV39)/9,"On-hold"),"Aborted"),"Closed"),"RIP") -> 0.44444444 | AM39: 45607 | AN39: 45607 | AO39: na | AP39: 45607 | AQ39: 45607 | AW39: 45607 | BC39: |
B40: =IF(D40=$A$516,1,IF(D40=$A$517,2,IF(D40=$A$518,3,IF(D40=$A$519,4,IF(D40=$A$520,5,IF(D40=$A$521,6)))))) -> 3 | D40: =IF(AL40="Closed","cls",IF(AL40=1,"sgn",IF(AL40="On-hold","hld",IF(AL40="Aborted","abt",IF(AL40<1,"wip","RIP"))))) -> wip | E40: EUROSPITAL SpA | G40: TS | H40: 00047510326 | J40: Medical Equipment | K40: Produzione equipment e consumables per laboratori analisi | L40: Massimiliano Kropf | M40: Michele Kropf | N40: Massimiliano Kropf | P40: Massimiliano Kropf | S40: no | T40: 2023 | U40: 38.3 | V40: 3.7 | W40: =+V40/U40 -> 0.096605744 | X40: 1.5 | Y40: 0.5 | AA40: Relazione | AC40: FCA | AD40: FCA | AG40: Meet MEDICA 2024 | AI40: =+TODAY()-AM40 -> 55 | AJ40: =+(IF(AL40="Closed","-",IF(TODAY()-MAX(AN40:BA40)>0,TODAY()-MAX(AN40:BA40),0))) -> 55 | AK40: Sell Side | AL40: =+IF(BB40="",IF(AZ40="",IF(AY40="",IF(AX40="",COUNTA(AN40:AV40)/9,"On-hold"),"Aborted"),"Closed"),"RIP") -> 0.44444444 | AM40: 45609 | AN40: 45609 | AO40: na | AP40: 45609 | AQ40: 45609 | AW40: 45609 | BC40: |
B41: =IF(D41=$A$516,1,IF(D41=$A$517,2,IF(D41=$A$518,3,IF(D41=$A$519,4,IF(D41=$A$520,5,IF(D41=$A$521,6)))))) -> 3 | D41: =IF(AL41="Closed","cls",IF(AL41=1,"sgn",IF(AL41="On-hold","hld",IF(AL41="Aborted","abt",IF(AL41<1,"wip","RIP"))))) -> wip | E41: BORGHI SpA | G41: MO | H41: 03575150366 | J41: Machinery | K41: Produzione di macchine per l'industria delle spazzole | L41: Andrea Del Carlo | M41: Marco Solato | N41: Fabrizio Biagi | P41: Giampaolo Roversi | S41: no | T41: 2023 | U41: 33 | V41: 1.4 | W41: =+V41/U41 -> 0.042424242 | X41: 0.6 | Y41: 3.6 | AA41: Fiera | AC41: FCA | AD41: FCA | AG41: Meet MEDICA 2024 | AI41: =+TODAY()-AM41 -> 55 | AJ41: =+(IF(AL41="Closed","-",IF(TODAY()-MAX(AN41:BA41)>0,TODAY()-MAX(AN41:BA41),0))) -> 55 | AK41: Agevolato | AL41: =+IF(BB41="",IF(AZ41="",IF(AY41="",IF(AX41="",COUNTA(AN41:AV41)/9,"On-hold"),"Aborted"),"Closed"),"RIP") -> 0.44444444 | AM41: 45609 | AN41: 45609 | AO41: na | AP41: 45609 | AQ41: 45609 | AW41: 45609 | BC41: |
...

Sheet Int'l
E1: =+Tracking!$E$2 -> 2 | F1: NON MODIFICARE CELLE CONTENTENTI FORMULE | V1: Tracking | W1: =+COUNTIF($B:$B,1) -> 9 | Y1: WIP | Z1: =+COUNTIF($B:$B,2) -> 2 | AB1: Aborted | AC1: =+COUNTIF($B:$B,3) -> 181
AA2: |
C3: Status | D3: Flow | E3: Nome | F3: Int'l Partner | G3: Country | H3: Type of mandate | J3: Sector | K3: Description | L3: Partner’s Notes | N3: Relationship @BCA | O3: In Charge @BCA | Q3: Notes | S3: Days since idea | T3: Days since latest progress | V3: Idea | W3: First Contact | X3: Latest Progress | Y3: Status | AA3: |
AA4: |
B5: {=+_xlfn.IFS(C5="Tracking",2,C5="WIP",1,C5="Aborted",3)} -> 1 | C5: =+Y5 -> WIP | D5: Inbound | E5: Food packaging (pitch) | F5: JBR - GMAP | G5: Netherlands | H5: Sell | J5: Industrial | K5: Packaging (food and tobacco) | N5: ASC | S5: =+TODAY()-V5 -> 30 | T5: =+TODAY()-X5 -> 30 | V5: 45634 | W5: 45634 | X5: 45634 | Y5: WIP
B6: {=+_xlfn.IFS(C6="Tracking",2,C6="WIP",1,C6="Aborted",3)} -> 1 | C6: =+Y6 -> WIP | D6: Inbound | E6: Payment app (pitch) | F6: Saga Corporate Finance - GMAP | G6: Norway | H6: Sell | J6: Technology | K6: Payment app group (for bus ticketing, boat docking payments, doctor appointments etc) | N6: ASC | O6: LUS | S6: =+TODAY()-V6 -> 30 | T6: =+TODAY()-X6 -> 29 | V6: 45634 | W6: 45634 | X6: 45635 | Y6: WIP
B7: {=+_xlfn.IFS(C7="Tracking",2,C7="WIP",1,C7="Aborted",3)} -> 1 | C7: =+Y7 -> WIP | D7: Inbound | E7: Injection molding (automotive supplier) | F7: Invescom Corporate Finance - GMAP | G7: Romania | H7: Sell | J7: Industrial | K7: Plastic injection molding supplier in Romania | L7: Ricavi: €27M, EBITDA €5.4M | N7: LUS | O7: FCA | S7: =+TODAY()-V7 -> 36 | T7: =+TODAY()-X7 -> 29 | V7: 45628 | W7: 45628 | X7: 45635 | Y7: WIP
B8: {=+_xlfn.IFS(C8="Tracking",2,C8="WIP",1,C8="Aborted",3)} -> 1 | C8: =+Y8 -> WIP | D8: Inbound | E8: Fine foods (pitch) | F8: Financière de Courcelles - REACH | G8: France | H8: Sell | J8: Food | K8: Branded sea foods products | L8: EBITDA €5M | O8: LUS | S8: =+TODAY()-V8 -> 36 | T8: =+TODAY()-X8 -> 36 | V8: 45628 | W8: 45628 | X8: 45628 | Y8: WIP
B9: {=+_xlfn.IFS(C9="Tracking",2,C9="WIP",1,C9="Aborted",3)} -> 1 | C9: =+Y9 -> WIP | D9: Inbound | E9: Pj Fleming (pitch) | F9: Zeus Capital - REACH | G9: UK | H9: Sell | J9: Consumer | K9: Cleaning products | L9: Ricavi: £60M, EBITDA £16M | O9: LUS | S9: =+TODAY()-V9 -> 49 | T9: =+TODAY()-X9 -> 36 | V9: 45615 | W9: 45615 | X9: 45628 | Y9: WIP
B10: {=+_xlfn.IFS(C10="Tracking",2,C10="WIP",1,C10="Aborted",3)} -> 1 | C10: =+Y10 -> WIP | D10: Inbound | E10: Pj JACKHAMMER | F10: IOM - GMAP | G10: Germany | H10: Sell | J10: Industrial | K10: Demolition and building material recycling business | L10: Ricavi: €55M, EBITDA €7.5M | N10: ASC | O10: LUS | S10: =+TODAY()-V10 -> 78 | T10: =+TODAY()-X10 -> 68 | V10: 45586 | W10: 45586 | X10: 45596 | Y10: WIP
B11: {=+_xlfn.IFS(C11="Tracking",2,C11="WIP",1,C11="Aborted",3)} -> 1 | C11: =+Y11 -> WIP | D11: Outbound | E11: Add-on Almac (Wise) | F11: IOM - GMAP | G11: Germany | H11: Buy | J11: Industrial | K11: Lift platforms | N11: LOM | O11: PAD | S11: =+TODAY()-V11 -> 41 | T11: =+TODAY()-X11 -> 41 | V11: 45623 | W11: 45623 | X11: 45623 | Y11: WIP
B12: {=+_xlfn.IFS(C12="Tracking",2,C12="WIP",1,C12="Aborted",3)} -> 1 | C12: =+Y12 -> WIP | D12: Outbound | E12: Add-on Greenexta (Wise) | F12: Anquor - GMAP | G12: Spain | H12: Buy | J12: Agro | K12: Biostimolanti | N12: LOM | O12: PAD | S12: =+TODAY()-V12 -> 41 | T12: =+TODAY()-X12 -> 41 | V12: 45623 | W12: 45623 | X12: 45623 | Y12: WIP
B13: {=+_xlfn.IFS(C13="Tracking",2,C13="WIP",1,C13="Aborted",3)} -> 1 | C13: =+Y13 -> WIP | D13: Outbound | E13: Brembo | F13: Meridian Capital, Brown/Gibbson/Lang, Crosbie - REACH | G13: Italy | H13: Buy | J13: Automotive | K13: Braking and suspension systems | N13: FCA | O13: ASP | S13: =+TODAY()-V13 -> 98 | T13: =+TODAY()-X13 -> 41 | V13: 45566 | W13: 45602 | X13: 45623 | Y13: WIP
B14: {=+_xlfn.IFS(C14="Tracking",2,C14="WIP",1,C14="Aborted",3)} -> 2 | C14: =+Y14 -> Tracking | D14: Inbound | E14: Lone Rider | F14: Nash Advisory | G14: Australia | H14: Sell | J14: Consumer | K14: Premium Adventure Motorbike accessories | L14: Rev: $11M; Ebitda $3M | N14: FCA | O14: LUS | S14: =+TODAY()-V14 -> 106 | T14: =+TODAY()-X14 -> 106 | V14: 45558 | W14: 45558 | X14: 45558 | Y14: Tracking
B15: {=+_xlfn.IFS(C15="Tracking",2,C15="WIP",1,C15="Aborted",3)} -> 2 | C15: =+Y15 -> Tracking | D15: Outbound | E15: Fagioli PFW | G15: Italy | H15: Sell | J15: Logistics | K15: Project Forwarding | N15: ASC | O15: RIM | S15: =+TODAY()-V15 -> 64 | T15: =+TODAY()-X15 -> 64 | V15: 45600 | W15: 45600 | X15: 45600 | Y15: Tracking
B16: {=+_xlfn.IFS(C16="Tracking",2,C16="WIP",1,C16="Aborted",3)} -> 3 | C16: =+Y16 -> Aborted | D16: Inbound | E16: Pj Despatch | F16: Cooper Parry - REACH | G16: UK | H16: Sell | J16: Logistics | N16: ASC | O16: LUS | S16: =+TODAY()-V16 -> 76 | T16: =+TODAY()-X16 -> 28 | V16: 45588 | W16: 45588 | X16: 45636 | Y16: Aborted
B17: {=+_xlfn.IFS(C17="Tracking",2,C17="WIP",1,C17="Aborted",3)} -> 3 | C17: =+Y17 -> Aborted | D17: Outbound | E17: Pj Roar (Consilium) | F17: Zeus Capital, IOM, Anquor - REACH | G17: USA, Germany, Spain | H17: Buy | J17: Industrial | K17: Macchnari per lavorazione metalli | N17: ROS | O17: GIM | S17: =+TODAY()-V17 -> 79 | T17: =+TODAY()-X17 -> 42 | V17: 45585 | W17: 45585 | X17: 45622 | Y17: Aborted
B18: {=+_xlfn.IFS(C18="Tracking",2,C18="WIP",1,C18="Aborted",3)} -> 3 | C18: =+Y18 -> Aborted | D18: Inbound | E18: Bonatti (pitch) | F18: RIòN - GMAP | G18: Mexico | H18: Sell | J18: Energy | K18: General contractor Energy, Oli&Gas | N18: ASC | S18: =+TODAY()-V18 -> 151 | T18: =+TODAY()-X18 -> 134 | V18: 45513 | W18: 45528 | X18: 45530 | Y18: Aborted
B19: {=+_xlfn.IFS(C19="Tracking",2,C19="WIP",1,C19="Aborted",3)} -> 3 | C19: =+Y19 -> Aborted | D19: Inbound | E19: Pj MOLDANO | F19: Condere - GMAP | G19: Brasil | H19: Sell | J19: Industrial | K19: Mold maker | L19: Rev: c. $8M | N19: ASC | O19: GIM | Q19: Inviato a OMS Besser Group, non interessati | S19: =+TODAY()-V19 -> 286 | T19: =+TODAY()-X19 -> 119 | V19: 45378 | W19: 45383 | X19: 45545 | Y19: Aborted
B20: {=+_xlfn.IFS(C20="Tracking",2,C20="WIP",1,C20="Aborted",3)} -> 3 | C20: =+Y20 -> Aborted | D20: Inbound | E20: Pj CHASE | F20: IOM - GMAP | G20: Germany | H20: Sell | J20: Consumer | K20: Termocamere ad uso privato (caccia) e militare | L20: Ricavi: €10M, EBITDA €1M | N20: ASC | O20: LUS | S20: =+TODAY()-V20 -> 151 | T20: =+TODAY()-X20 -> 105 | V20: 45513 | W20: 45513 | X20: 45559 | Y20: Aborted
B21: {=+_xlfn.IFS(C21="Tracking",2,C21="WIP",1,C21="Aborted",3)} -> 3 | C21: =+Y21 -> Aborted | D21: Inbound | E21: Pj LABEL | F21: Total Finans - GMAP | G21: Turkey | H21: Sell | J21: Industrial | K21: Self adhesive labels | L21: Rev: $25M; Ebitda $3M | N21: ASC | O21: LUS | S21: =+TODAY()-V21 -> 196 | T21: =+TODAY()-X21 -> 127 | V21: 45468 | W21: 45468 | X21: 45537 | Y21: Aborted
B22: {=+_xlfn.IFS(C22="Tracking",2,C22="WIP",1,C22="Aborted",3)} -> 3 | C22: =+Y22 -> Aborted | D22: Inbound | E22: Pj COAST | F22: BGLCO - GMAP | G22: US | H22: Sell | J22: Food | K22: Rumiano Cheese (Branded and private label organic retail) cheese and contract processor | L22: Rev: $120M; Ebitda $7M | N22: FCA | O22: LUS | S22: =+TODAY()-V22 -> 224 | T22: =+TODAY()-X22 -> 106 | V22: 45440 | W22: 45440 | X22: 45558 | Y22: Aborted
B23: {=+_xlfn.IFS(C23="Tracking",2,C23="WIP",1,C23="Aborted",3)} -> 3 | C23: =+Y23 -> Aborted | D23: Inbound | E23: Italian Pharma Manufacturers | F23: Invescom Corporate Finance - GMAP | G23: Hungary | H23: Buy | J23: Pharma | K23: Polish company looking for italian pharma targets | L23: Ricavi €20-70M | N23: FCA | S23: =+TODAY()-V23 -> 217 | T23: =+TODAY()-X23 -> 211 | V23: 45447 | W23: 45449 | X23: 45453 | Y23: Aborted
B24: {=+_xlfn.IFS(C24="Tracking",2,C24="WIP",1,C24="Aborted",3)} -> 3 | C24: =+Y24 -> Aborted | D24: Outbound | E24: EFC Acciai | F24: IOM - FDC - TotalFinans | G24: Italy | H24: Sell | J24: Industrial | K24: Tubificio | N24: ASC | O24: RIM | P24: PAD | S24: =+TODAY()-V24 -> 169 | T24: =+TODAY()-X24 -> 169 | V24: 45495 | W24: 45495 | X24: 45495 | Y24: Aborted
B25: {=+_xlfn.IFS(C25="Tracking",2,C25="WIP",1,C25="Aborted",3)} -> 3 | C25: =+Y25 -> Aborted | D25: Outbound | E25: Stewart | F25: IOM - FDC | G25: Italy | H25: Sell | J25: Pharma | K25: R&D di farmaci per pediatria e ginecologia | N25: LOM | O25: RIM | S25: =+TODAY()-V25 -> 165 | T25: =+TODAY()-X25 -> 165 | V25: 45499 | W25: 45499 | X25: 45499 | Y25: Aborted
B26: {=+_xlfn.IFS(C26="Tracking",2,C26="WIP",1,C26="Aborted",3)} -> 3 | C26: =+Y26 -> Aborted | D26: Outbound | E26: CDZ Vini Srl | F26: Anquor Corporate Finance - GMAP | G26: Spain | H26: Sell | J26: Food: Wine | K26: Winery | L26: Ricavi: €28M, EBITDA €4M | N26: ROS | O26: LUS | S26: =+TODAY()-V26 -> 224 | T26: =+TODAY()-X26 -> 224 | V26: 45440 | W26: 45440 | X26: 45440 | Y26: Aborted
B27: {=+_xlfn.IFS(C27="Tracking",2,C27="WIP",1,C27="Aborted",3)} -> 3 | C27: =+Y27 -> Aborted | D27: Outbound | E27: Pj PORPORA (CDZ Vini) | F27: Anquor Corporate Finance - GMAP | G27: Spain | H27: Sell | J27: Food&Beverage | K27: Casa vinicola | L27: Rev: €28M, Ebitda: €4M | N27: ROS | O27: LUS | S27: =+TODAY()-V27 -> 239 | T27: =+TODAY()-X27 -> 237 | V27: 45425 | W27: 45425 | X27: 45427 | Y27: Aborted
B28: {=+_xlfn.IFS(C28="Tracking",2,C28="WIP",1,C28="Aborted",3)} -> 3 | C28: =+Y28 -> Aborted | D28: Inbound | E28: Groupe H4 | F28: Financière de Courcelles - GMAP | G28: France | H28: Sell | J28: Services | K28: Brand (Jaym) di cover e accessori smartphone | L28: Rev: c. €10M | N28: ASC | O28: RIM | S28: =+TODAY()-V28 -> 351 | T28: =+TODAY()-X28 -> 349 | V28: 45313 | W28: 45313 | X28: 45315 | Y28: Aborted
B29: {=+_xlfn.IFS(C29="Tracking",2,C29="WIP",1,C29="Aborted",3)} -> 3 | C29: =+Y29 -> Aborted | D29: Inbound | E29: Haier Smart Home | F29: Condere - GMAP | G29: Brasil | H29: Buy | J29: Technology | K29: Soluzioni IoT per la casa | L29: - | N29: ASC | O29: LUS | S29: =+TODAY()-V29 -> 321 | T29: =+TODAY()-X29 -> 321 | V29: 45343 | W29: 45343 | X29: 45343 | Y29: Aborted | AA29: |
B30: {=+_xlfn.IFS(C30="Tracking",2,C30="WIP",1,C30="Aborted",3)} -> 3 | C30: =+Y30 -> Aborted | D30: Outbound | E30: Industrie Chimiche Forestali | F30: GMAP | G30: Italy | H30: Sell | J30: Industrial | K30: Produzione di colle e riforzanti per diversi settori industriali | L30: Ricavi: €88M, EBITDA €8M | N30: ASC | O30: RIM | S30: =+TODAY()-V30 -> 439 | T30: =+TODAY()-X30 -> 439 | V30: 45225 | W30: 45225 | X30: 45225 | Y30: Aborted
B31: {=+_xlfn.IFS(C31="Tracking",2,C31="WIP",1,C31="Aborted",3)} -> 3 | C31: =+Y31 -> Aborted | D31: Outbound | E31: Spica (Pj. Card) | F31: GMAP | G31: Italy | H31: Sell | J31: Industrial | K31: PVC films manufacturer | N31: ASC | O31: RIM | S31: =+TODAY()-V31 -> 328 | T31: =+TODAY()-X31 -> 328 | V31: 45336 | W31: 45336 | X31: 45336 | Y31: Aborted
B32: {=+_xlfn.IFS(C32="Tracking",2,C32="WIP",1,C32="Aborted",3)} -> 3 | C32: =+Y32 -> Aborted | D32: Inbound | E32: Stoll Trucks | F32: Financière de Courcelles - GMAP | G32: Luxembourg | H32: Buy | J32: Automotive | K32: One-stop-services for commercial vehicles, Heavy trucks and Bus | L32: Revenue: € 70M, EBITDA: € 9-10M | N32: FCA | O32: MMO | Q32: Close proximity to management and the investment fund. We need to work on the buy side | S32: =+TODAY()-V32 -> 336 | T32: =+TODAY()-X32 -> 336 | V32: 45328 | W32: =+V32 -> 45328 | X32: =+W32 -> 45328 | Y32: Aborted
B33: {=+_xlfn.IFS(C33="Tracking",2,C33="WIP",1,C33="Aborted",3)} -> 3 | C33: =+Y33 -> Aborted | D33: Inbound | E33: Groupe LT | F33: Financière de Courcelles - GMAP | G33: France | H33: Buy | J33: Industrial | K33: Worksite equipment rental and service provider | L33: - | N33: LOM | O33: LUS | S33: =+TODAY()-V33 -> 358 | T33: =+TODAY()-X33 -> 358 | V33: 45306 | W33: 45306 | X33: 45306 | Y33: Aborted
B34: {=+_xlfn.IFS(C34="Tracking",2,C34="WIP",1,C34="Aborted",3)} -> 3 | C34: =+Y34 -> Aborted | D34: Outbound | E34: Target ProA (Pergole/Tende) | F34: Financière de Courcelles - GMAP | G34: Italy | H34: Buy | J34: Industrial | K34: Produzione di schermature solari | L34: EBITDA >€3M | N34: LOM | O34: PAD | S34: =+TODAY()-V34 -> 361 | T34: =+TODAY()-X34 -> 358 | V34: 45303 | W34: 45303 | X34: 45306 | Y34: Aborted
B35: {=+_xlfn.IFS(C35="Tracking",2,C35="WIP",1,C35="Aborted",3)} -> 3 | C35: =+Y35 -> Aborted | D35: Outbound | E35: Target ProA (HR) | F35: Financière de Courcelles - GMAP | G35: Italy | H35: Buy | J35: Services | K35: Personale interinale e HR | L35: EBITDA >€3M | N35: LOM | O35: PAD | S35: =+TODAY()-V35 -> 361 | T35: =+TODAY()-X35 -> 358 | V35: 45303 | W35: 45303 | X35: 45306 | Y35: Aborted
B36: {=+_xlfn.IFS(C36="Tracking",2,C36="WIP",1,C36="Aborted",3)} -> 3 | C36: =+Y36 -> Aborted | D36: Outbound | E36: Target Riverside (BioDue) | F36: Anquor Corporate Finance - GMAP | G36: Italy | H36: Buy | J36: Pharma | K36: Produzione di colle e riforzanti per diversi settori industriali | L36: EBITDA >€5M | N36: ASC | S36: =+TODAY()-V36 -> 389 | T36: =+TODAY()-X36 -> 361 | V36: 45275 | W36: 45275 | X36: 45303 | Y36: Aborted
B37: {=+_xlfn.IFS(C37="Tracking",2,C37="WIP",1,C37="Aborted",3)} -> 3 | C37: =+Y37 -> Aborted | D37: Inbound | E37: Nobis | F37: Crossbie | G37: Canada | H37: Sell | J37: Fashion & Luxury | K37: Luxury apparel brand | L37: Rev: $25M | N37: ASC | O37: LUS | S37: =+TODAY()-V37 -> 419 | T37: =+TODAY()-X37 -> 411 | V37: 45245 | W37: 45245 | X37: 45253 | Y37: Aborted
B38: {=+_xlfn.IFS(C38="Tracking",2,C38="WIP",1,C38="Aborted",3)} -> 3 | C38: =+Y38 -> Aborted | D38: Inbound | E38: Pelagos | F38: RIòN - GMAP | G38: Mexico | H38: Sell | J38: Food | K38: Fishing, processing, and commercializing sardines | L38: Rev: $86M; Ebitda $29m | N38: LOM | O38: LUS | S38: =+TODAY()-V38 -> 480 | T38: =+TODAY()-X38 -> 480 | V38: 45184 | W38: 45184 | X38: 45184 | Y38: Aborted
B39: {=+_xlfn.IFS(C39="Tracking",2,C39="WIP",1,C39="Aborted",3)} -> 3 | C39: =+Y39 -> Aborted | D39: Inbound | E39: Epicure | F39: Financière de Courcelles - GMAP | G39: France | H39: Sell | J39: Food | K39: Gourmet food (focus: tartufo) | L39: Ricavi: €30M, EBITDA €4M | N39: LOM | O39: LUS | S39: =+TODAY()-V39 -> 489 | T39: =+TODAY()-X39 -> 489 | V39: 45175 | W39: 45175 | X39: 45175 | Y39: Aborted
B40: {=+_xlfn.IFS(C40="Tracking",2,C40="WIP",1,C40="Aborted",3)} -> 3 | C40: =+Y40 -> Aborted | D40: Outbound | E40: Stam | F40: GMAP | G40: Italy | H40: Sell | J40: Industrial | K40: Produzione di linee di profilatura e di taglio della lamiera | L40: Rev: €30M; Ebitda €5m | N40: ASC | O40: RIM | P40: LUS | S40: =+TODAY()-V40 -> 502 | T40: =+TODAY()-X40 -> 502 | V40: 45162 | W40: 45162 | X40: 45162 | Y40: Aborted
...

Sheet Fondi_PE
C1: =+COUNTA(C3:C121)-1 -> 117 | M1: x | W1: =+COUNTA(W3:W121)-1 -> 5 | X1: =+COUNTA(X3:X121)-1 -> 5 | Y1: =+COUNTA(Y3:Y121)-1 -> 12 | Z1: =+COUNTA(Z3:Z121)-1 -> 11 | AA1: =+COUNTA(AA3:AA121)-1 -> 6 | AB1: =+COUNTA(AB3:AB121)-1 -> 4 | AC1: =+COUNTA(AC3:AC121)-1 -> 2 | AD1: =+COUNTA(AD3:AD121)-1 -> 3 | ... BT1: =+COUNTA(BT3:BT121)-1 -> 0 | BY1: |
B2: Cnt | C2: SGR / Società di investimento | D2: Sito WEB | E2: Tipologia | F2: Nome Fondo | G2: Raccolta | H2: Anno Raccolta | I2: Sweet Spot Ticket | J2: Sweet Spot EBITDA | K2: Focus settori | L2: Partner ns riferimento | M2: x | N2: Relazione @BCA | O2: Staff_1 | P2: Staff_2 | Q2: Note | S2: #Eventi | T2: Latest Event | U2: Days since | W2: 45313 | X2: =+W2+7 -> 45320 | Y2: =+X2+7 -> 45327 | Z2: =+Y2+7 -> 45334 | AA2: =+Z2+7 -> 45341 | AB2: =+AA2+7 -> 45348 | AC2: =+AB2+7 -> 45355 | AD2: =+AC2+7 -> 45362 | AE2: =+AD2+7 -> 45369 | ... BW2: =+BV2+7 -> 45677 | BX2: INSERIRE PRIMA DI QUESTA COLONNA | BY2: |
C3: 21 Invest | E3: Fondo PE | G3: 320 | H3: 2023 | I3: 20-50M€ | K3: Generalista | L3: Andrea Mazzuccato | N3: ASC | Q3: Con ROS | S3: =+COUNTA(W3:BX3) -> 6 | T3: 45540 | U3: =IF(T3>0,IF(TODAY()>T3,TODAY()-T3,""),"") -> 124 | Y3: SILFA | Z3: SPICA | AM3: FACE | BC3: Meeting | BG3: GPS, Zaini | BJ3: Call | BY3: |
C4: 21 Invest - Healthcare | E4: Fondo PE | G4: 150 | H4: 2024 | I4: 10 - 15M€ | K4: Healthcare | L4: Fabio Parisi | N4: ASC | O4: PAD | S4: =+COUNTA(W4:BX4) -> 7 | T4: 45630 | U4: =IF(T4>0,IF(TODAY()>T4,TODAY()-T4,""),"") -> 34 | Y4: SILFA | Z4: SPICA | AM4: FACE | BC4: Meeting | BG4: GPS, Zaini | BJ4: Call | BP4: Wimed | BY4: |
C5: 360 Capital | E5: Fondo VC | L5: Cesare Maifredi | N5: ASC | O5: RIM | Q5: Tramite Davide Corrias (Allianz) | S5: =+COUNTA(W5:BX5) -> 1 | T5: 45643 | U5: =IF(T5>0,IF(TODAY()>T5,TODAY()-T5,""),"") -> 21 | BV5: Meeting | BY5: |
A6: A | C6: Accel | E6: Fondo VC | L6: Luca Bocchio | N6: FCA | O6: ASP | S6: =+COUNTA(W6:BX6) -> 1 | T6: 45502 | U6: =IF(T6>0,IF(TODAY()>T6,TODAY()-T6,""),"") -> 162 | AX6: PMC | BY6: |
C7: A-Green | E7: Club Deal | L7: Andrea Rossi | N7: FCA | S7: =+COUNTA(W7:BX7) -> 0 | U7: =IF(T7>0,IF(TODAY()>T7,TODAY()-T7,""),"") | BY7: |
C8: Aksìa | D8: www.aksiagroup.com/it | E8: Fondo PE | F8: Aksia Capital V | G8: 275 | H8: 2022 | I8: 10 - 20M€ | K8: Generalista | L8: Marco Rayneri | M8: x | N8: ASC | O8: PAD | S8: =+COUNTA(W8:BX8) -> 1 | T8: 45432 | U8: =IF(T8>0,IF(TODAY()>T8,TODAY()-T8,""),"") -> 232 | AN8: Myes | BY8: |
C9: Alcedo | E9: Fondo PE | K9: Generalista | L9: Alessandro Zanet | N9: ASC | O9: RIM | Q9: ASC con Nalon | S9: =+COUNTA(W9:BX9) -> 4 | T9: 45436 | U9: =IF(T9>0,IF(TODAY()>T9,TODAY()-T9,""),"") -> 228 | AB9: Fusto | AN9: Sapori Veri; Myes | BF9: Mars | BK9: Call | BY9: |
C10: Algebris | E10: Fondo PE | I10: 10 - 20M€ | L10: Stefano Sostero | M10: x | N10: ASC | S10: =+COUNTA(W10:BX10) -> 3 | T10: 45327 | U10: =IF(T10>0,IF(TODAY()>T10,TODAY()-T10,""),"") -> 337 | Y10: SILFA | Z10: SPICA | BF10: Mars | BY10: |
C11: Alpha Generator Capital | E11: Search Fund | K11: Generalista | L11: Federico Di Benedetto | N11: ASC | O11: GIM | P11: GID | S11: =+COUNTA(W11:BX11) -> 1 | T11: 45614 | U11: =IF(T11>0,IF(TODAY()>T11,TODAY()-T11,""),"") -> 50 | BN11: Call | BY11: |
C12: Alto Partners | E12: Fondo PE | G12: 270 | H12: 2023 | I12: 20-50M€ | K12: Generalista | L12: Gianmarco Gandolfi | N12: LOM | S12: =+COUNTA(W12:BX12) -> 7 | T12: 45432 | U12: =IF(T12>0,IF(TODAY()>T12,TODAY()-T12,""),"") -> 232 | W12: Fra' Diavolo | AL12: Fusto | AN12: Myes | AR12: FUA | AS12: Olimpia | BC12: Meeting | BK12: Target Fra Diavolo Polonia | BY12: |
C13: Ambienta | D13: https://ambientasgr.com/ | E13: Fondo PE | F13: Ambienta SGR | G13: 1550 | H13: 2022 | I13: 10 - 20M€ | K13: Sostenibilità | L13: Gianfranco Beraudo Francesco Lodrini | M13: x | N13: ASC | S13: =+COUNTA(W13:BX13) -> 2 | T13: 45544 | U13: =IF(T13>0,IF(TODAY()>T13,TODAY()-T13,""),"") -> 120 | AD13: meeting | BD13: Kilometro Verde | BY13: |
C14: Amundi SGR | E14: Fondo PE | G14: 100 | H14: 2023 | I14: 5 - 10M€ | K14: Generalista | L14: Viviana Gasparrini | M14: x | N14: ASC | Q14: Minoranze "growth" o in co-investimento su LBOs | S14: =+COUNTA(W14:BX14) -> 5 | T14: 45449 | U14: =IF(T14>0,IF(TODAY()>T14,TODAY()-T14,""),"") -> 215 | AO14: Fusto | AP14: Sapori Veri | BD14: Olimpia | BI14: Mars | BM14: Meeting | BY14: |
C15: ANDERA Capital | E15: Fondo PE | F15: V Fondo Mid-cap | G15: 650 | I15: 20-50M€ | K15: Generalista | L15: Francesco Gonzaga | N15: ASC | Q15: Sia Min sia Magg | S15: =+COUNTA(W15:BX15) -> 1 | T15: 45588 | U15: =IF(T15>0,IF(TODAY()>T15,TODAY()-T15,""),"") -> 76 | BJ15: Forum Mergermarket | BY15: |
C16: Anemos Private Investments (Gruppo Samhita) | D16: https://samhitainvestments.com/about-us-anemos/ | E16: Fondo PE | K16: Generalista | L16: Martina Di Gioia | N16: ASC | O16: GIM | S16: =+COUNTA(W16:BX16) -> 1 | T16: 45590 | U16: =IF(T16>0,IF(TODAY()>T16,TODAY()-T16,""),"") -> 74 | BJ16: Incontro | BY16: |
C17: Anthilia | E17: Private Debt | K17: Generalista | L17: Tobia Dian | O17: RIM | S17: =+COUNTA(W17:BX17) -> 1 | T17: 45356 | U17: =IF(T17>0,IF(TODAY()>T17,TODAY()-T17,""),"") -> 308 | AJ17: Fusto + Sapori Veri | BY17: |
C18: Arcadia | E18: Fondo PE | G18: 100M€ | H18: 2024 | I18: 5 - 20M€ | J18: 4 - 8M€ | K18: Generalista | L18: Giovanni Barbujani | N18: ASC | S18: =+COUNTA(W18:BX18) -> 2 | T18: 45562 | U18: =IF(T18>0,IF(TODAY()>T18,TODAY()-T18,""),"") -> 102 | AU18: Call | BE18: Sapori Veri | BY18: |
C19: Archimed | E19: Fondo PE | F19: Healthcare | L19: Igor Petricca | N19: FCA | S19: =+COUNTA(W19:BX19) -> 2 | T19: 45369 | U19: =IF(T19>0,IF(TODAY()>T19,TODAY()-T19,""),"") -> 295 | AA19: Meeting | AE19: Vismederi + Theras | BY19: |
C20: Argos Wityu | D20: https://argos.wityu.fund/it/ | E20: Fondo PE | F20: Euroknights VII | G20: 650 | H20: 2021 | K20: Generalista | L20: Lucio Ranaudo | M20: xx | N20: ASC | O20: RIM | P20: GID | S20: =+COUNTA(W20:BX20) -> 4 | T20: 45478 | U20: =IF(T20>0,IF(TODAY()>T20,TODAY()-T20,""),"") -> 186 | X20: Elogy | Y20: SILFA | Z20: SPICA | AU20: Meeting | BY20: |
C21: Armira | D21: https://www.armira.de/en/ | E21: Inv Holding | I21: >50M€ | K21: Healthcare&Technology | L21: Leopold Walde | N21: FCA | S21: =+COUNTA(W21:BX21) -> 6 | T21: 45404 | U21: =IF(T21>0,IF(TODAY()>T21,TODAY()-T21,""),"") -> 260 | AD21: Meeting | AI21: Meeting | AJ21: Meeting | AQ21: Elmec Informatica | AT21: Elmec Informatica | BD21: Elmec Informatica - visit | BY21: |
C22: Atlas Partners | E22: Search Fund | L22: Stefano Carpano | N22: ASC | O22: PAD | S22: =+COUNTA(W22:BX22) -> 2 | T22: 45405 | U22: =IF(T22>0,IF(TODAY()>T22,TODAY()-T22,""),"") -> 259 | BH22: Bitta | BJ22: Edera | BY22: |
C23: Auctus | E23: Fondo PE | L23: Marco Bortot | N23: FCA | S23: =+COUNTA(W23:BX23) -> 3 | T23: 45406 | U23: =IF(T23>0,IF(TODAY()>T23,TODAY()-T23,""),"") -> 258 | Y23: Next HS Spica Silfa | Z23: SILFA | BF23: Wave, Maestro, Pixel (meeting) | BY23: |
C24: Augens | E24: Inv Holding | I24: 20-50M€ | K24: Generalista | L24: Massimo Puccio - Marco Mantica | M24: x | N24: ASC | Q24: Cercano cluster come HOFI | S24: =+COUNTA(W24:BX24) -> 2 | T24: 45434 | U24: =IF(T24>0,IF(TODAY()>T24,TODAY()-T24,""),"") -> 230 | W24: Call | AN24: Myes | BY24: |
